2021-02-08 00:47:35,755 ERROR: Exception on /logi [GET] [in /home/purplerain/Documents/python/flask/test/venv/lib/python3.8/site-packages/flask/app.py:1891]
Traceback (most recent call last):
  File "/home/purplerain/Documents/python/flask/test/venv/lib/python3.8/site-packages/sqlalchemy/engine/base.py", line 1276, in _execute_context
    self.dialect.do_execute(
  File "/home/purplerain/Documents/python/flask/test/venv/lib/python3.8/site-packages/sqlalchemy/engine/default.py", line 609, in do_execute
    cursor.execute(statement, parameters)
psycopg2.errors.UndefinedTable: ОШИБКА:  отношение "user" не существует
LINE 2: FROM "user" 
             ^


The above exception was the direct cause of the following exception:

Traceback (most recent call last):
  File "/home/purplerain/Documents/python/flask/test/venv/lib/python3.8/site-packages/flask/app.py", line 2447, in wsgi_app
    response = self.full_dispatch_request()
  File "/home/purplerain/Documents/python/flask/test/venv/lib/python3.8/site-packages/flask/app.py", line 1952, in full_dispatch_request
    rv = self.handle_user_exception(e)
  File "/home/purplerain/Documents/python/flask/test/venv/lib/python3.8/site-packages/flask/app.py", line 1821, in handle_user_exception
    reraise(exc_type, exc_value, tb)
  File "/home/purplerain/Documents/python/flask/test/venv/lib/python3.8/site-packages/flask/_compat.py", line 39, in reraise
    raise value
  File "/home/purplerain/Documents/python/flask/test/venv/lib/python3.8/site-packages/flask/app.py", line 1948, in full_dispatch_request
    rv = self.preprocess_request()
  File "/home/purplerain/Documents/python/flask/test/venv/lib/python3.8/site-packages/flask/app.py", line 2242, in preprocess_request
    rv = func()
  File "/home/purplerain/Documents/python/flask/microblog-0.8/app/routes.py", line 12, in before_request
    if current_user.is_authenticated:
  File "/home/purplerain/Documents/python/flask/test/venv/lib/python3.8/site-packages/werkzeug/local.py", line 347, in __getattr__
    return getattr(self._get_current_object(), name)
  File "/home/purplerain/Documents/python/flask/test/venv/lib/python3.8/site-packages/werkzeug/local.py", line 306, in _get_current_object
    return self.__local()
  File "/home/purplerain/Documents/python/flask/test/venv/lib/python3.8/site-packages/flask_login/utils.py", line 26, in <lambda>
    current_user = LocalProxy(lambda: _get_user())
  File "/home/purplerain/Documents/python/flask/test/venv/lib/python3.8/site-packages/flask_login/utils.py", line 346, in _get_user
    current_app.login_manager._load_user()
  File "/home/purplerain/Documents/python/flask/test/venv/lib/python3.8/site-packages/flask_login/login_manager.py", line 318, in _load_user
    user = self._user_callback(user_id)
  File "/home/purplerain/Documents/python/flask/microblog-0.8/app/models.py", line 65, in load_user
    return User.query.get(int(id))
  File "/home/purplerain/Documents/python/flask/test/venv/lib/python3.8/site-packages/sqlalchemy/orm/query.py", line 1018, in get
    return self._get_impl(ident, loading.load_on_pk_identity)
  File "/home/purplerain/Documents/python/flask/test/venv/lib/python3.8/site-packages/sqlalchemy/orm/query.py", line 1135, in _get_impl
    return db_load_fn(self, primary_key_identity)
  File "/home/purplerain/Documents/python/flask/test/venv/lib/python3.8/site-packages/sqlalchemy/orm/loading.py", line 286, in load_on_pk_identity
    return q.one()
  File "/home/purplerain/Documents/python/flask/test/venv/lib/python3.8/site-packages/sqlalchemy/orm/query.py", line 3490, in one
    ret = self.one_or_none()
  File "/home/purplerain/Documents/python/flask/test/venv/lib/python3.8/site-packages/sqlalchemy/orm/query.py", line 3459, in one_or_none
    ret = list(self)
  File "/home/purplerain/Documents/python/flask/test/venv/lib/python3.8/site-packages/sqlalchemy/orm/query.py", line 3535, in __iter__
    return self._execute_and_instances(context)
  File "/home/purplerain/Documents/python/flask/test/venv/lib/python3.8/site-packages/sqlalchemy/orm/query.py", line 3560, in _execute_and_instances
    result = conn.execute(querycontext.statement, self._params)
  File "/home/purplerain/Documents/python/flask/test/venv/lib/python3.8/site-packages/sqlalchemy/engine/base.py", line 1011, in execute
    return meth(self, multiparams, params)
  File "/home/purplerain/Documents/python/flask/test/venv/lib/python3.8/site-packages/sqlalchemy/sql/elements.py", line 298, in _execute_on_connection
    return connection._execute_clauseelement(self, multiparams, params)
  File "/home/purplerain/Documents/python/flask/test/venv/lib/python3.8/site-packages/sqlalchemy/engine/base.py", line 1124, in _execute_clauseelement
    ret = self._execute_context(
  File "/home/purplerain/Documents/python/flask/test/venv/lib/python3.8/site-packages/sqlalchemy/engine/base.py", line 1316, in _execute_context
    self._handle_dbapi_exception(
  File "/home/purplerain/Documents/python/flask/test/venv/lib/python3.8/site-packages/sqlalchemy/engine/base.py", line 1510, in _handle_dbapi_exception
    util.raise_(
  File "/home/purplerain/Documents/python/flask/test/venv/lib/python3.8/site-packages/sqlalchemy/util/compat.py", line 182, in raise_
    raise exception
  File "/home/purplerain/Documents/python/flask/test/venv/lib/python3.8/site-packages/sqlalchemy/engine/base.py", line 1276, in _execute_context
    self.dialect.do_execute(
  File "/home/purplerain/Documents/python/flask/test/venv/lib/python3.8/site-packages/sqlalchemy/engine/default.py", line 609, in do_execute
    cursor.execute(statement, parameters)
sqlalchemy.exc.ProgrammingError: (psycopg2.errors.UndefinedTable) ОШИБКА:  отношение "user" не существует
LINE 2: FROM "user" 
             ^

[SQL: SELECT "user".id AS user_id, "user".username AS user_username, "user".email AS user_email, "user".password_hash AS user_password_hash, "user".about_me AS user_about_me, "user".last_seen AS user_last_seen 
FROM "user" 
WHERE "user".id = %(param_1)s]
[parameters: {'param_1': 1}]
(Background on this error at: http://sqlalche.me/e/13/f405)
